Workbook

Sheet Assumptions
A1: CAPCOM CO., LTD. — COMPREHENSIVE ASSUMPTIONS
A2: All figures in ¥ millions unless noted | Fiscal Year ends March 31
A4: Metric | B4: FY2021 | C4: FY2022 | D4: FY2023 | E4: FY2024 | F4: FY2025 | G4: AY26E | H4: AY27E | I4: AY28E | J4: Calculation Source / Justification
A6: SECTION 1: HISTORICAL FINANCIAL DATA (FY2021-FY2025)
A8: Consolidated Revenue (¥M) | B8: 95308 | C8: 110054 | D8: 125930 | E8: 152410 | F8: 169604 | J8: Source: Compiled Financials, FY2021-FY2025 Actuals
A9: Total Unit Sales (millions) | B9: 30.1 | C9: 32.6 | D9: 41.7 | E9: 45.893 | F9: 51.876 | J9: Source: Integrated Report 2025, p.24
A10: YoY Revenue Growth % | C10: =C8/B8-1 -> 0.15471944 | D10: =D8/C8-1 -> 0.14425646 | E10: =E8/D8-1 -> 0.21027555 | F10: =F8/E8-1 -> 0.11281412 | J10: Calculated: (Current Year / Prior Year) - 1
A11: Digital Sales Mix % | B11: 0.681 | C11: 0.703 | D11: 0.736 | E11: 0.791 | F11: 0.761 | J11: Source: Integrated Report 2025, trend p.24
A12: Catalog Sales Mix % | B12: 0.681 | C12: 0.791 | D12: 0.761 | E12: 0.791 | F12: 0.791 | J12: Source: Integrated Report 2025, p.15
A14: SECTION 2: REVENUE PROJECTIONS BY SEGMENT (Bottom-Up Build)
A16: Business Segment | F16: FY2025A | G16: AY26E | H16: AY27E | I16: AY28E | J16: Driver / Justification
A17: Digital Contents (¥M) | F17: 125128 | G17: 141000 | H17: 155000 | I17: 169000 | J17: MH Wilds full-year (10.1M→15.5M) + RE Requiem launch + 79% catalog retention
A18: Arcade Operations (¥M) | F18: 22750 | G18: 24500 | H18: 26000 | I18: 27500 | J18: Inbound tourism recovery (45M visitors by AY28) + 4 new stores/year expansion
A19: Amusement Equipment (¥M) | F19: 15613 | G19: 17500 | H19: 19000 | I19: 20500 | J19: Smart Slot penetration (RE Village 10,400 units → 12,000 units/year)
A20: Other Businesses (¥M) | F20: 6111 | G20: 7000 | H20: 7650 | I20: 8000 | J20: eSports (SF6 tournaments) + IP licensing expansion + Netflix anime
A21: TOTAL CONSOLIDATED REVENUE | F21: =SUM(F17:F20) -> 169602 | G21: =SUM(G17:G20) -> 190000 | H21: =SUM(H17:H20) -> 207650 | I21: =SUM(I17:I20) -> 225000 | J21: Sum of all business segments
A22: YoY Growth % | G22: =G21/F21-1 -> 0.12026981 | H22: =H21/G21-1 -> 0.092894737 | I22: =I21/H21-1 -> 0.083554057 | J22: Implied growth from segment buildup
A24: SECTION 3: DETAILED UNIT SALES PROJECTIONS
A26: Unit Sales Category | F26: FY2025A | G26: AY26E | H26: AY27E | I26: AY28E | J26: Calculation Method
A27: New Titles (M units) | F27: 12.4 | G27: 16.2 | H27: 16.4 | I27: 16.6 | J27: MH Wilds (10.1M→15.5M) + RE Requiem (0.5M→6.0M) + pipeline
A28: Catalog Titles (M units) | F28: 39.5 | G28: 37.8 | H28: 42.1 | I28: 47.4 | J28: 78% retention of prior year catalog base + new title carryover
A29: Digital Units (M) | F29: 39.5 | G29: =(F27+F28)*0.78 -> 40.482 | H29: =(G27+G28)*0.8 -> 43.2 | I29: =(H27+H28)*0.82 -> 47.97 | J29: Total units × Digital % (76.1% → 78% → 80% → 82% trend)
A30: Physical Units (M) | F30: 12.4 | G30: =F27+F28-G29 -> 11.418 | H30: =G27+G28-H29 -> 10.8 | I30: =H27+H28-I29 -> 10.53 | J30: Total units - Digital units (declining trend)
A31: TOTAL UNITS (M) | F31: =F27+F28 -> 51.9 | G31: =G27+G28 -> 54 | H31: =H27+H28 -> 58.5 | I31: =I27+I28 -> 64 | J31: New Titles + Catalog Titles (path to 100M target: 64%)
A33: SECTION 4: PROFITABILITY ASSUMPTIONS
A35: Margin Metric | F35: FY2025 | G35: AY26E | H35: AY27E | I35: AY28E | J35: Source / Justification
A36: Gross Margin % | F36: 0.582 | G36: 0.585 | H36: 0.598 | I36: 0.605 | J36: Digital mix expansion (76%→82%) + catalog scale = margin improvement
A37: SG&A as % of Revenue | F37: 0.194 | G37: 0.195 | H37: 0.193 | I37: 0.191 | J37: FY21-25 avg: 18.3%; slightly elevated for global expansion investments
A38: Operating Margin % (Implied) | F38: =F36-F37 -> 0.388 | G38: =G36-G37 -> 0.39 | H38: =H36-H37 -> 0.405 | I38: =I36-I37 -> 0.414 | J38: Gross Margin - SG&A% = Operating Margin
A39: Effective Tax Rate % | F39: 0.263 | G39: 0.26 | H39: 0.26 | I39: 0.258 | J39: FY21-25 avg: 26.2%; Japan corporate tax rate ~26%
A41: SECTION 5: DCF VALUATION ASSUMPTIONS
A43: DCF Parameter | F43: Value | J43: Source / Calculation
A44: Risk-Free Rate (JGB 10Y) | F44: 0.01 | J44: Japan 10-Year Government Bond Yield (as of Jan 2026)
A45: Equity Risk Premium | F45: 0.055 | J45: Japanese market ERP: 5.5% (historical average)
A46: Beta (5Y) | F46: 1.4 | J46: Source: Bloomberg, 5-year monthly beta vs TOPIX
A47: Cost of Equity (CAPM) | F47: =F44+(F45*F46) -> 0.087 | J47: Risk-Free Rate + (Beta × ERP)
A48: WACC (≈Cost of Equity) | F48: =F47 -> 0.087 | J48: Minimal debt → WACC ≈ Cost of Equity
A49: Terminal Growth Rate | F49: 0.025 | J49: Conservative: Japan GDP growth + 0.5%
A51: SECTION 6: MARKET DATA & VALUATION INPUTS
A53: Market Metric | F53: Value | J53: Source / Note
...

Sheet Income Statement
A1: CAPCOM CO., LTD. — CONSOLIDATED INCOME STATEMENT
A2: ¥ millions | Fiscal Year ending March 31
A4: Line Item | B4: FY2021 | C4: FY2022 | D4: FY2023 | E4: FY2024 | F4: FY2025 | G4: AY26E | H4: AY27E | I4: AY28E
A6: Net Sales | B6: 95308 | C6: 110054 | D6: 125930 | E6: 152410 | F6: 169604 | G6: =Assumptions!G21 -> 190000 | H6: =Assumptions!H21 -> 207650 | I6: =Assumptions!I21 -> 225000
A7: YoY Growth | C7: =C6/B6-1 -> 0.15471944 | D7: =D6/C6-1 -> 0.14425646 | E7: =E6/D6-1 -> 0.21027555 | F7: =F6/E6-1 -> 0.11281412 | G7: =G6/F6-1 -> 0.1202566 | H7: =H6/G6-1 -> 0.092894737 | I7: =I6/H6-1 -> 0.083554057
A9: Cost of Revenue | B9: -42567 | C9: -48736 | D9: -52130 | E9: -67750 | F9: -70901 | G9: =-G6*(1-Assumptions!G36) -> -78850 | H9: =-H6*(1-Assumptions!H36) -> -83475.3 | I9: =-I6*(1-Assumptions!I36) -> -88875
A10: Gross Profit | B10: =B6+B9 -> 52741 | C10: =C6+C9 -> 61318 | D10: =D6+D9 -> 73800 | E10: =E6+E9 -> 84660 | F10: =F6+F9 -> 98703 | G10: =G6+G9 -> 111150 | H10: =H6+H9 -> 124174.7 | I10: =I6+I9 -> 136125
A11: Gross Margin % | B11: =B10/B6 -> 0.55337432 | C11: =C10/C6 -> 0.55716285 | D11: =D10/D6 -> 0.58603986 | E11: =E10/E6 -> 0.55547536 | F11: =F10/F6 -> 0.58196151 | G11: =G10/G6 -> 0.585 | H11: =H10/H6 -> 0.598 | I11: =I10/I6 -> 0.605
A13: SG&A Expenses | B13: -18145 | C13: -18408 | D13: -23000 | E13: -27564 | F13: -32969 | G13: =-G6*Assumptions!G37 -> -37050 | H13: =-H6*Assumptions!H37 -> -40076.45 | I13: =-I6*Assumptions!I37 -> -42975
A14: Operating Income | B14: =B10+B13 -> 34596 | C14: =C10+C13 -> 42910 | D14: =D10+D13 -> 50800 | E14: =E10+E13 -> 57096 | F14: =F10+F13 -> 65734 | G14: =G10+G13 -> 74100 | H14: =H10+H13 -> 84098.25 | I14: =I10+I13 -> 93150
A15: Operating Margin % | B15: =B14/B6 -> 0.36299156 | C15: =C14/C6 -> 0.3898995 | D15: =D14/D6 -> 0.40339871 | E15: =E14/E6 -> 0.37462109 | F15: =F14/F6 -> 0.38757341 | G15: =G14/G6 -> 0.39 | H15: =H14/H6 -> 0.405 | I15: =I14/I6 -> 0.414
A17: Non-Operating Income/(Expense) | B17: -9 | C17: -9 | D17: 0 | E17: 600 | F17: 1200 | G17: 600 | H17: 700 | I17: 800
A18: Pretax Income | B18: =B14+B17 -> 34587 | C18: =C14+C17 -> 42901 | D18: =D14+D17 -> 50800 | E18: =E14+E17 -> 57696 | F18: =F14+F17 -> 66934 | G18: =G14+G17 -> 74700 | H18: =H14+H17 -> 84798.25 | I18: =I14+I17 -> 93950
A19: Income Tax Expense | B19: -11768 | C19: -11768 | D19: -14075 | E19: -13706 | F19: -17151 | G19: =-G18*Assumptions!G39 -> -19422 | H19: =-H18*Assumptions!H39 -> -22047.545 | I19: =-I18*Assumptions!I39 -> -24239.1
A21: Net Income | B21: =B18+B19 -> 22819 | C21: =C18+C19 -> 31133 | D21: =D18+D19 -> 36725 | E21: =E18+E19 -> 43990 | F21: =F18+F19 -> 49783 | G21: =G18+G19 -> 55278 | H21: =H18+H19 -> 62750.705 | I21: =I18+I19 -> 69710.9
A22: Net Margin % | B22: =B21/B6 -> 0.23942376 | C22: =C21/C6 -> 0.2828884 | D22: =D21/D6 -> 0.29163027 | E22: =E21/E6 -> 0.28862936 | F22: =F21/F6 -> 0.29352492 | G22: =G21/G6 -> 0.29093684 | H22: =H21/H6 -> 0.30219458 | I22: =I21/I6 -> 0.30982622
A24: Depreciation & Amortization | B24: 5500 | C24: 5800 | D24: 6100 | E24: 6500 | F24: 7000 | G24: 7500 | H24: 8000 | I24: 8500
A26: EBITDA | B26: =B14+B24 -> 40096 | C26: =C14+C24 -> 48710 | D26: =D14+D24 -> 56900 | E26: =E14+E24 -> 63596 | F26: =F14+F24 -> 72734 | G26: =G14+G24 -> 81600 | H26: =H14+H24 -> 92098.25 | I26: =I14+I24 -> 101650
A27: EBITDA Margin % | B27: =B26/B6 -> 0.42069921 | C27: =C26/C6 -> 0.44260091 | D27: =D26/D6 -> 0.45183832 | E27: =E26/E6 -> 0.41726921 | F27: =F26/F6 -> 0.42884602 | G27: =G26/G6 -> 0.42947368 | H27: =H26/H6 -> 0.44352637 | I27: =I26/I6 -> 0.45177778

Sheet Explanations
A1: CAPCOM FINANCIAL MODEL — COMPREHENSIVE EXPLANATIONS
A3: ASSUMPTIONS SHEET
A4: Section 1: Historical Data | B4: All historical data (FY2021-FY2025) sourced from:
B5: • Compiled Financials workbook (revenue, profits, balance sheet)
B6: • Integrated Report 2025 (unit sales, digital mix, catalog mix)
B7: • Company 10-K equivalent filings for Japan
A9: Section 2: Segment Projections | B9: Bottom-up revenue build by business segment:
B10: • Digital Contents: Based on unit sales × ASP, catalog retention analysis
B11: - MH Wilds: 10.1M (FY25) → 15.5M (AY26) full-year sales
B12: - RE Requiem: Conservative 4.5M first year, 6M lifetime
B13: - Catalog: 79% of total, 78% retention rate
B14: • Arcade Operations: Inbound tourism recovery (45M visitors target)
B15: - 4 new stores/year expansion, improving SSSG
B16: • Amusement Equipment: Smart Slot penetration driving growth
B17: - RE Village units: 10,400 → 12,000/year
B18: • Other: eSports growth (SF6), licensing, Netflix anime deals
A20: Section 3: Unit Sales | B20: Detailed unit economic projections:
B21: • New Titles: Pipeline visibility (MH Wilds, RE Requiem)
B22: • Catalog: 78% retention from Complete Analysis
B23: • Digital Mix: 76.1% → 78% → 80% → 82% (trend analysis)
B24: • Physical: Declining as digital expands
A26: Section 4: Margins | B26: Profitability drivers:
B27: • Gross Margin: Digital mix expansion drives improvement
B28: - Higher digital % = lower COGS (no manufacturing/distribution)
B29: - Catalog scale economies
B30: • SG&A: 19.5% assumption includes global expansion investments
B31: - FY21-25 historical average: 18.3%
B32: - Slightly elevated for marketing, localization
B33: • Tax Rate: 26% based on Japan corporate tax, FY21-25 avg: 26.2%
A35: Section 5: DCF Inputs | B35: Valuation parameters:
B36: • Risk-Free Rate: 1.0% (JGB 10-Year)
B37: • ERP: 5.5% (Japan market historical)
B38: • Beta: 1.40 (5-year vs TOPIX)
B39: • WACC ≈ Cost of Equity (minimal debt)
B40: • Terminal Growth: 2.5% (conservative)
A42: INCOME STATEMENT
A43: Formula Logic | B43: All projections formula-driven from Assumptions:
B44: • Revenue: =Assumptions sheet segment totals
B45: • COGS: =Revenue × (1 - Gross Margin%)
B46: • SG&A: =Revenue × SG&A%
...

Sheet Balance Sheet
A1: CAPCOM CO., LTD. — Consolidated Balance Sheet
A2: ¥ millions | As of March 31
B4: FY2022 | C4: FY2023 | D4: FY2024 | E4: FY2025
A6: ASSETS
A7: Cash & Cash Equivalents | B7: 89470 | C7: 95635 | D7: 109091 | E7: 150426
A8: Other Current Assets | B8: 77600 | C8: 82324 | D8: 103917 | E8: 128857
A9: Total Current Assets | B9: =B7+B8 -> 167070 | C9: =C7+C8 -> 177959 | D9: =D7+D8 -> 213008 | E9: =E7+E8 -> 279283
A10: PP&E, net | B10: 18200 | C10: 20500 | D10: 22000 | E10: 25000
A11: Intangible Assets & Goodwill | B11: 1747 | C11: 1630 | D11: 1444 | E11: 1436
A12: Other Non-Current Assets | B12: 348 | C12: 6276 | D12: 7024 | E12: 7263
A13: Total Non-Current Assets | B13: =B10+B11+B12 -> 20295 | C13: =C10+C11+C12 -> 28406 | D13: =D10+D11+D12 -> 30468 | E13: =E10+E11+E12 -> 33699
A14: TOTAL ASSETS | B14: =B9+B13 -> 187365 | C14: =C9+C13 -> 206365 | D14: =D9+D13 -> 243476 | E14: =E9+E13 -> 312982
A16: LIABILITIES & EQUITY
A17: Total Current Liabilities | B17: 46495 | C17: 52376 | D17: 48395 | E17: 57600
A18: Total Non-Current Liabilities | B18: 6105 | C18: 3860 | D18: 7841 | E18: 29079
A19: Total Liabilities | B19: =B17+B18 -> 52600 | C19: =C17+C18 -> 56236 | D19: =D17+D18 -> 56236 | E19: =E17+E18 -> 86679
A20: Total Equity | B20: 146475 | C20: 161129 | D20: 195081 | E20: 226303
A21: TOTAL LIABILITIES & EQUITY | B21: =B19+B20 -> 199075 | C21: =C19+C20 -> 217365 | D21: =D19+D20 -> 251317 | E21: =E19+E20 -> 312982
A23: KEY RATIOS
A24: Equity Ratio | B24: =B20/B14 -> 0.78176287 | C24: =C20/C14 -> 0.78079616 | D24: =D20/D14 -> 0.80123298 | E24: =E20/E14 -> 0.72305436
A25: Net Cash (Cash - Total Debt) | B25: =B7-B18 -> 83365 | C25: =C7-C18 -> 91775 | D25: =D7-D18 -> 101250 | E25: =E7-E18 -> 121347
A26: ROE | C26: ='Income Statement'!D21/AVERAGE(B20,C20) -> 0.23878103 | D26: ='Income Statement'!E21/AVERAGE(C20,D20) -> 0.24698914 | E26: ='Income Statement'!F21/AVERAGE(D20,E20) -> 0.2362833

Sheet Cash Flow
A1: CAPCOM CO., LTD. — Cash Flow Statement
A2: ¥ millions | Fiscal Year ending March 31
B4: FY2021 | C4: FY2022 | D4: FY2023 | E4: FY2024 | F4: FY2025 | G4: FY2026E | H4: FY2027E | I4: FY2028E
A6: Operating Cash Flow | B6: 46947 | C6: 21789 | D6: 36921 | E6: 67618 | F6: 58049 | G6: ='Income Statement'!G21+'Income Statement'!G24+5000 -> 67778 | H6: ='Income Statement'!H21+'Income Statement'!H24+3000 -> 73750.705 | I6: ='Income Statement'!I21+'Income Statement'!I24+2000 -> 80210.9
A8: Capital Expenditures | B8: -4067 | C8: -7415 | D8: -5135 | E8: -6277 | F8: -14436 | G8: -15000 | H8: -12000 | I8: -12000
A9: Other Investing Activities | B9: -3359 | C9: -264 | D9: -827 | E9: -997 | F9: -26405 | G9: -5000 | H9: -3000 | I9: -2000
A10: Investing Cash Flow | B10: =B8+B9 -> -7426 | C10: =C8+C9 -> -7679 | D10: =D8+D9 -> -5962 | E10: =E8+E9 -> -7274 | F10: =F8+F9 -> -40841 | G10: =G8+G9 -> -20000 | H10: =H8+H9 -> -15000 | I10: =I8+I9 -> -14000
A12: Dividends Paid | B12: -5200 | C12: -7686 | D12: -9670 | E12: -11396 | F12: -16835 | G12: -18000 | H12: -20000 | I12: -22000
A13: Debt Repayment / Other Financing | B13: -4780 | C13: -14799 | D13: -6299 | E13: -7339 | F13: -8501 | G13: -5000 | H13: -5000 | I13: -5000
A14: Financing Cash Flow | B14: =B12+B13 -> -9980 | C14: =C12+C13 -> -22485 | D14: =D12+D13 -> -15969 | E14: =E12+E13 -> -18735 | F14: =F12+F13 -> -25336 | G14: =G12+G13 -> -23000 | H14: =H12+H13 -> -25000 | I14: =I12+I13 -> -27000
A16: Free Cash Flow (OCF - CapEx) | B16: =B6+B8 -> 42880 | C16: =C6+C8 -> 14374 | D16: =D6+D8 -> 31786 | E16: =E6+E8 -> 61341 | F16: =F6+F8 -> 43613 | G16: =G6+G8 -> 52778 | H16: =H6+H8 -> 61750.705 | I16: =I6+I8 -> 68210.9
A17: FCF Margin | B17: =B16/'Income Statement'!B6 -> 0.44990977 | C17: =C16/'Income Statement'!C6 -> 0.13060861 | D17: =D16/'Income Statement'!D6 -> 0.25241007 | E17: =E16/'Income Statement'!E6 -> 0.40247359 | F17: =F16/'Income Statement'!F6 -> 0.25714606 | G17: =G16/'Income Statement'!G6 -> 0.27777895 | H17: =H16/'Income Statement'!H6 -> 0.29737879 | I17: =I16/'Income Statement'!I6 -> 0.30315956
A19: Net Change in Cash | B19: =B6+B10+B14 -> 29541 | C19: =C6+C10+C14 -> -8375 | D19: =D6+D10+D14 -> 14990 | E19: =E6+E10+E14 -> 41609 | F19: =F6+F10+F14 -> -8128 | G19: =G6+G10+G14 -> 24778 | H19: =H6+H10+H14 -> 33750.705 | I19: =I6+I10+I14 -> 39210.9

Sheet Valuation
A1: CAPCOM CO., LTD. — Valuation
A2: ¥ millions unless noted
A4: DISCOUNTED CASH FLOW (DCF)
B5: FY2026E | C5: FY2027E | D5: FY2028E | E5: Terminal
A7: Free Cash Flow | B7: ='Cash Flow'!G16 -> 52778 | C7: ='Cash Flow'!H16 -> 61750.705 | D7: ='Cash Flow'!I16 -> 68210.9
A8: Terminal Value | E8: =D7*(1+Assumptions!F49)/(Assumptions!F48-Assumptions!F49) -> 1127680.2
A9: WACC | B9: =Assumptions!F48 -> 0.087
A10: Discount Factor | B10: =1/(1+B9)^1 -> 0.9199632 | C10: =1/(1+B9)^2 -> 0.84633229 | D10: =1/(1+B9)^3 -> 0.77859456 | E10: =1/(1+B9)^3 -> 0.77859456
A11: PV of Cash Flows | B11: =B7*B10 -> 48553.818 | C11: =C7*C10 -> 52261.616 | D11: =D7*D10 -> 53108.636 | E11: =E8*E10 -> 878005.68
A13: Sum of PV (FCFs) | B13: =SUM(B11:D11) -> 153924.07
A14: PV of Terminal Value | B14: =E11 -> 878005.68
A15: Enterprise Value (DCF) | B15: =B13+B14 -> 1031929.7
A16: (+) Net Cash | B16: =Assumptions!F57 -> 97000
A17: Equity Value (DCF) | B17: =B15+B16 -> 1128929.7
A18: Shares Outstanding (thousands) | B18: =Assumptions!F55 -> 533000
A19: Implied Share Price (¥) | B19: =B17*1000/B18 -> 2118.0671
A20: Current Price (¥) | B20: =Assumptions!F54 -> 2843
A21: Upside / (Downside) | B21: =B19/B20-1 -> -0.25498872
A23: TRADING MULTIPLES ANALYSIS
B24: FY2025A | C24: FY2026E | D24: FY2027E
A26: EV / EBITDA | B26: =Assumptions!F58/'Income Statement'!F26 -> 19.500082 | C26: =Assumptions!F58/'Income Statement'!G26 -> 17.38136 | D26: =Assumptions!F58/'Income Statement'!H26 -> 15.400065
A27: EV / EBIT (Operating Income) | B27: =Assumptions!F58/'Income Statement'!F14 -> 21.576642 | C27: =Assumptions!F58/'Income Statement'!G14 -> 19.140607 | D27: =Assumptions!F58/'Income Statement'!H14 -> 16.865024
A28: P/E Ratio | B28: =Assumptions!F56/'Income Statement'!F21 -> 30.438483 | C28: =Assumptions!F56/'Income Statement'!G21 -> 27.412696 | D28: =Assumptions!F56/'Income Statement'!H21 -> 24.148239
A29: P / FCF | B29: =Assumptions!F56/'Cash Flow'!F16 -> 34.744663 | C29: =Assumptions!F56/'Cash Flow'!G16 -> 28.711186
A30: Dividend Yield | B30: =Assumptions!F60 -> 0.012
A32: PEER COMPARISON (FY2025/LTM)
A33: Company | B33: EV/EBITDA | C33: P/E | D33: Op. Margin | E33: Rev Growth
A34: Capcom (9697) | B34: =B26 -> 19.500082 | C34: =B28 -> 30.438483 | D34: ='Income Statement'!F15 -> 0.38757341 | E34: ='Income Statement'!F7 -> 0.11281412
A35: Nintendo (7974) | B35: 14 | C35: 20 | D35: 0.33 | E35: 0.35
A36: Square Enix (9684) | B36: 8.5 | C36: 25 | D36: 0.12 | E36: 0.05
A37: Konami (9766) | B37: 15 | C37: 28 | D37: 0.22 | E37: 0.1
A38: Bandai Namco (7832) | B38: 12 | C38: 22 | D38: 0.1 | E38: 0.08
A39: EA (NASDAQ) | B39: 16 | C39: 30 | D39: 0.2 | E39: 0.02
A40: Peer Average (excl. Capcom) | B40: =AVERAGE(B35:B39) -> 13.1 | C40: =AVERAGE(C35:C39) -> 25 | D40: =AVERAGE(D35:D39) -> 0.194 | E40: =AVERAGE(E35:E39) -> 0.12
A42: IMPLIED PRICE FROM PEER MULTIPLES
A43: At Peer Avg EV/EBITDA → EV | B43: =B40*'Income Statement'!G27 -> 5.6261053
A44: → Equity Value | B44: =B43+Assumptions!F57 -> 97005.626
A45: → Implied Share Price (¥) | B45: =B44*1000/Assumptions!F55 -> 181.9993
A46: At Peer Avg P/E → Market Cap | B46: =C40*'Income Statement'!G21 -> 1381950
A47: → Implied Share Price (¥) | B47: =B46*1000/Assumptions!F55 -> 2592.7767

Sheet Valuation Methodology
A1: CAPCOM VALUATION METHODOLOGY
A2: Detailed explanation of valuation techniques with updated assumptions
A4: 1. VALUATION APPROACH OVERVIEW
A6: Valuation Method | B6: Purpose | C6: Weight | D6: Rationale
A7: Discounted Cash Flow (DCF) | B7: Intrinsic value from future cash flows | C7: 50% | D7: Stable, profitable company with predictable FCF
A8: Comparable Companies | B8: Relative value vs. peers | C8: 30% | D8: Validates DCF against market pricing
A9: Scenario Analysis | B9: Risk-adjusted range | C9: 20% | D9: Captures game release uncertainty
A12: 2. WACC CALCULATION (UPDATED)
A14: Component | B14: Value | C14: Source
A15: Risk-Free Rate (Rf) | B15: 1.0% | C15: JGB 10-Year yield
A16: Equity Risk Premium | B16: 5.5% | C16: Japan historical ERP
A17: Beta (β) | B17: 1.40 | C17: Bloomberg 5Y monthly vs TOPIX (updated)
A18: Cost of Equity (CAPM) | B18: 8.7% | C18: Ke = 1.0% + 1.40 × 5.5%
A19: WACC | B19: 8.7% | C19: Net cash position → WACC ≈ Ke
A22: 3. REVENUE PROJECTION METHODOLOGY
A24: Segment | B24: AY26E Projection | C24: Key Driver
A25: Digital Contents | B25: ¥141B (+12.7%) | C25: MH Wilds DLC + RE Requiem launch + catalog
A26: Arcade Operations | B26: ¥24.5B (+7.7%) | C26: Inbound tourism recovery, 4 new stores/yr
A27: Amusement Equipment | B27: ¥17.5B (+12.1%) | C27: Smart Slot penetration, RE Village units
A28: Other Businesses | B28: ¥7.0B (+14.5%) | C28: SF6 eSports + IP licensing expansion
A29: TOTAL | B29: ¥190B (+12.0%) | C29: Bottom-up segment buildup
A32: 4. UNIT SALES ASSUMPTIONS
A34: Category | B34: FY25A | C34: AY26E | D34: Rationale
A35: New Titles | B35: 12.4M | C35: 16.2M | D35: MH Wilds full year + RE Requiem
A36: Catalog Titles | B36: 39.5M | C36: 37.8M | D36: 78% retention rate applied
A37: Digital Mix | B37: 76.1% | C37: 78% | D37: Continued digital transition
A38: Total Units | B38: 51.9M | C38: 54.0M | D38: Path to 100M unit target
A41: 5. PROFITABILITY ASSUMPTIONS
A43: Metric | B43: FY25A | C43: AY26E | D43: Driver
A44: Gross Margin | B44: 58.2% | C44: 58.5% | D44: Digital mix expansion (76%→78%)
A45: SG&A % | B45: 19.4% | C45: 19.5% | D45: Marketing investment (FY21-25 avg: 18.3%)
A46: Operating Margin | B46: 38.8% | C46: 39.0% | D46: Scale leverage + catalog efficiency
A47: Tax Rate | B47: 26.3% | C47: 26.0% | D47: Japan corporate tax rate
A50: 6. DCF VALUATION FORMULA
A52: Enterprise Value = Σ [FCFt / (1 + WACC)^t] + Terminal Value / (1 + WACC)^n Where: • FCF = Net Income + D&A - CapEx - ΔNWC (simplified: from Cash Flow sheet) • WACC = 8.7% (Cost of Equity, minimal debt) • Terminal Value = Final Year FCF × (1 + g) / (WACC - g) • g = 2.5% (terminal growth rate) Equity Value = Enterprise Value + Net Cash (¥97B) Implied Share Price = Equity Value × 1000 / Shares Outstanding (533M)
A54: 7. KEY ASSUMPTIONS & RISKS
A56: Assumption | B56: Base Case | C56: Risk | D56: Mitigant
A57: Revenue Growth | B57: 12% FY26E | C57: MH Wilds DLC underperforms | D57: Catalog provides floor; RE Requiem diversifies
A58: Operating Margin | B58: 39% | C58: Marketing costs increase | D58: 83%+ digital mix supports margins
A59: Beta | B59: 1.40 | C59: Volatility increases | D59: Net cash reduces financial risk
...

Sheet Sensitivity
A1: SENSITIVITY ANALYSIS
A2: Implied Share Price under different WACC / Terminal Growth scenarios
A4: Terminal Growth ↓ / WACC → | B4: 0.03 | C4: 0.035 | D4: 0.04 | E4: 0.042 | F4: 0.05 | G4: 0.055
A5: 0.015 | B5: =(Valuation!B7/(1+0.03)^1+Valuation!C7/(1+0.03)^2+(Valuation!D7+Valuation!D7*(1+$A5)/(0.03-$A5))/(1+0.03)^3+Assumptions!F57)*1000/Assumptions!F55 -> 8429.2703 | C5: =(Valuation!B7/(1+0.035)^1+Valuation!C7/(1+0.035)^2+(Valuation!D7+Valuation!D7*(1+$A5)/(0.035-$A5))/(1+0.035)^3+Assumptions!F57)*1000/Assumptions!F55 -> 6359.134 | D5: =(Valuation!B7/(1+0.04)^1+Valuation!C7/(1+0.04)^2+(Valuation!D7+Valuation!D7*(1+$A5)/(0.04-$A5))/(1+0.04)^3+Assumptions!F57)*1000/Assumptions!F55 -> 5117.1342 | E5: =(Valuation!B7/(1+0.042)^1+Valuation!C7/(1+0.042)^2+(Valuation!D7+Valuation!D7*(1+$A5)/(0.042-$A5))/(1+0.042)^3+Assumptions!F57)*1000/Assumptions!F55 -> 4749.1552 | F5: =(Valuation!B7/(1+0.05)^1+Valuation!C7/(1+0.05)^2+(Valuation!D7+Valuation!D7*(1+$A5)/(0.05-$A5))/(1+0.05)^3+Assumptions!F57)*1000/Assumptions!F55 -> 3697.8774 | G5: =(Valuation!B7/(1+0.055)^1+Valuation!C7/(1+0.055)^2+(Valuation!D7+Valuation!D7*(1+$A5)/(0.055-$A5))/(1+0.055)^3+Assumptions!F57)*1000/Assumptions!F55 -> 3254.433
A6: 0.02 | B6: =IFERROR((Valuation!B7/(1+0.03)^1+Valuation!C7/(1+0.03)^2+(Valuation!D7+Valuation!D7*(1+$A6)/(0.03-$A6))/(1+0.03)^3+Assumptions!F57)*1000/Assumptions!F55,0) -> 12450.241 | C6: =IFERROR((Valuation!B7/(1+0.035)^1+Valuation!C7/(1+0.035)^2+(Valuation!D7+Valuation!D7*(1+$A6)/(0.035-$A6))/(1+0.035)^3+Assumptions!F57)*1000/Assumptions!F55,0) -> 8350.2411 | D6: =IFERROR((Valuation!B7/(1+0.04)^1+Valuation!C7/(1+0.04)^2+(Valuation!D7+Valuation!D7*(1+$A6)/(0.04-$A6))/(1+0.04)^3+Assumptions!F57)*1000/Assumptions!F55,0) -> 6300.3389 | E6: =IFERROR((Valuation!B7/(1+0.042)^1+Valuation!C7/(1+0.042)^2+(Valuation!D7+Valuation!D7*(1+$A6)/(0.042-$A6))/(1+0.042)^3+Assumptions!F57)*1000/Assumptions!F55,0) -> 5741.2992 | F6: =IFERROR((Valuation!B7/(1+0.05)^1+Valuation!C7/(1+0.05)^2+(Valuation!D7+Valuation!D7*(1+$A6)/(0.05-$A6))/(1+0.05)^3+Assumptions!F57)*1000/Assumptions!F55,0) -> 4250.6273 | G6: =IFERROR((Valuation!B7/(1+0.055)^1+Valuation!C7/(1+0.055)^2+(Valuation!D7+Valuation!D7*(1+$A6)/(0.055-$A6))/(1+0.055)^3+Assumptions!F57)*1000/Assumptions!F55,0) -> 3665.0753
A7: 0.025 | B7: =IFERROR((Valuation!B7/(1+0.03)^1+Valuation!C7/(1+0.03)^2+(Valuation!D7+Valuation!D7*(1+$A7)/(0.03-$A7))/(1+0.03)^3+Assumptions!F57)*1000/Assumptions!F55,0) -> 24513.152 | C7: =IFERROR((Valuation!B7/(1+0.035)^1+Valuation!C7/(1+0.035)^2+(Valuation!D7+Valuation!D7*(1+$A7)/(0.035-$A7))/(1+0.035)^3+Assumptions!F57)*1000/Assumptions!F55,0) -> 12332.455 | D7: =IFERROR((Valuation!B7/(1+0.04)^1+Valuation!C7/(1+0.04)^2+(Valuation!D7+Valuation!D7*(1+$A7)/(0.04-$A7))/(1+0.04)^3+Assumptions!F57)*1000/Assumptions!F55,0) -> 8272.3468 | E7: =IFERROR((Valuation!B7/(1+0.042)^1+Valuation!C7/(1+0.042)^2+(Valuation!D7+Valuation!D7*(1+$A7)/(0.042-$A7))/(1+0.042)^3+Assumptions!F57)*1000/Assumptions!F55,0) -> 7317.0572 | F7: =IFERROR((Valuation!B7/(1+0.05)^1+Valuation!C7/(1+0.05)^2+(Valuation!D7+Valuation!D7*(1+$A7)/(0.05-$A7))/(1+0.05)^3+Assumptions!F57)*1000/Assumptions!F55,0) -> 5024.4772 | G7: =IFERROR((Valuation!B7/(1+0.055)^1+Valuation!C7/(1+0.055)^2+(Valuation!D7+Valuation!D7*(1+$A7)/(0.055-$A7))/(1+0.055)^3+Assumptions!F57)*1000/Assumptions!F55,0) -> 4212.5983
A8: 0.03 | B8: =IFERROR((Valuation!B7/(1+0.03)^1+Valuation!C7/(1+0.03)^2+(Valuation!D7+Valuation!D7*(1+$A8)/(0.03-$A8))/(1+0.03)^3+Assumptions!F57)*1000/Assumptions!F55,0) -> 0 | C8: =IFERROR((Valuation!B7/(1+0.035)^1+Valuation!C7/(1+0.035)^2+(Valuation!D7+Valuation!D7*(1+$A8)/(0.035-$A8))/(1+0.035)^3+Assumptions!F57)*1000/Assumptions!F55,0) -> 24279.098 | D8: =IFERROR((Valuation!B7/(1+0.04)^1+Valuation!C7/(1+0.04)^2+(Valuation!D7+Valuation!D7*(1+$A8)/(0.04-$A8))/(1+0.04)^3+Assumptions!F57)*1000/Assumptions!F55,0) -> 12216.363 | E8: =IFERROR((Valuation!B7/(1+0.042)^1+Valuation!C7/(1+0.042)^2+(Valuation!D7+Valuation!D7*(1+$A8)/(0.042-$A8))/(1+0.042)^3+Assumptions!F57)*1000/Assumptions!F55,0) -> 10205.947 | F8: =IFERROR((Valuation!B7/(1+0.05)^1+Valuation!C7/(1+0.05)^2+(Valuation!D7+Valuation!D7*(1+$A8)/(0.05-$A8))/(1+0.05)^3+Assumptions!F57)*1000/Assumptions!F55,0) -> 6185.252 | G8: =IFERROR((Valuation!B7/(1+0.055)^1+Valuation!C7/(1+0.055)^2+(Valuation!D7+Valuation!D7*(1+$A8)/(0.055-$A8))/(1+0.055)^3+Assumptions!F57)*1000/Assumptions!F55,0) -> 4979.1304
A9: 0.035 | B9: =IFERROR((Valuation!B7/(1+0.03)^1+Valuation!C7/(1+0.03)^2+(Valuation!D7+Valuation!D7*(1+$A9)/(0.03-$A9))/(1+0.03)^3+Assumptions!F57)*1000/Assumptions!F55,0) -> -23738.492 | C9: =IFERROR((Valuation!B7/(1+0.035)^1+Valuation!C7/(1+0.035)^2+(Valuation!D7+Valuation!D7*(1+$A9)/(0.035-$A9))/(1+0.035)^3+Assumptions!F57)*1000/Assumptions!F55,0) -> 0 | D9: =IFERROR((Valuation!B7/(1+0.04)^1+Valuation!C7/(1+0.04)^2+(Valuation!D7+Valuation!D7*(1+$A9)/(0.04-$A9))/(1+0.04)^3+Assumptions!F57)*1000/Assumptions!F55,0) -> 24048.41 | E9: =IFERROR((Valuation!B7/(1+0.042)^1+Valuation!C7/(1+0.042)^2+(Valuation!D7+Valuation!D7*(1+$A9)/(0.042-$A9))/(1+0.042)^3+Assumptions!F57)*1000/Assumptions!F55,0) -> 17221.822 | F9: =IFERROR((Valuation!B7/(1+0.05)^1+Valuation!C7/(1+0.05)^2+(Valuation!D7+Valuation!D7*(1+$A9)/(0.05-$A9))/(1+0.05)^3+Assumptions!F57)*1000/Assumptions!F55,0) -> 8119.8767 | G9: =IFERROR((Valuation!B7/(1+0.055)^1+Valuation!C7/(1+0.055)^2+(Valuation!D7+Valuation!D7*(1+$A9)/(0.055-$A9))/(1+0.055)^3+Assumptions!F57)*1000/Assumptions!F55,0) -> 6128.9287
B10: =IFERROR((Valuation!B7/(1+0.03)^1+Valuation!C7/(1+0.03)^2+(Valuation!D7+Valuation!D7*(1+$A10)/(0.03-$A10))/(1+0.03)^3+Assumptions!F57)*1000/Assumptions!F55,0) -> 4408.3 | C10: =IFERROR((Valuation!B7/(1+0.035)^1+Valuation!C7/(1+0.035)^2+(Valuation!D7+Valuation!D7*(1+$A10)/(0.035-$A10))/(1+0.035)^3+Assumptions!F57)*1000/Assumptions!F55,0) -> 3799.1392 | D10: =IFERROR((Valuation!B7/(1+0.04)^1+Valuation!C7/(1+0.04)^2+(Valuation!D7+Valuation!D7*(1+$A10)/(0.04-$A10))/(1+0.04)^3+Assumptions!F57)*1000/Assumptions!F55,0) -> 3342.3271 | E10: =IFERROR((Valuation!B7/(1+0.042)^1+Valuation!C7/(1+0.042)^2+(Valuation!D7+Valuation!D7*(1+$A10)/(0.042-$A10))/(1+0.042)^3+Assumptions!F57)*1000/Assumptions!F55,0) -> 3190.0718 | F10: =IFERROR((Valuation!B7/(1+0.05)^1+Valuation!C7/(1+0.05)^2+(Valuation!D7+Valuation!D7*(1+$A10)/(0.05-$A10))/(1+0.05)^3+Assumptions!F57)*1000/Assumptions!F55,0) -> 2702.9276 | G10: =IFERROR((Valuation!B7/(1+0.055)^1+Valuation!C7/(1+0.055)^2+(Valuation!D7+Valuation!D7*(1+$A10)/(0.055-$A10))/(1+0.055)^3+Assumptions!F57)*1000/Assumptions!F55,0) -> 2470.4797
A11: SCENARIO ANALYSIS
A12: Scenario | B12: Rev Growth | C12: Op Margin | D12: Implied EPS (¥) | E12: At 25x P/E → Price (¥)
A13: Bear Case | B13: 0.08 | C13: 0.37 | D13: =Assumptions!F21*(1+B13)*C13*(1-Assumptions!G39)*1000000/Assumptions!F55/1000 -> 94.09379 | E13: =D13*25 -> 2352.3447
A14: Base Case | B14: 0.12 | C14: 0.39 | D14: =Assumptions!F21*(1+B14)*C14*(1-Assumptions!G39)*1000000/Assumptions!F55/1000 -> 102.85327 | E14: =D14*25 -> 2571.3318
A15: Bull Case | B15: 0.15 | C15: 0.41 | D15: =Assumptions!F21*(1+B15)*C15*(1-Assumptions!G39)*1000000/Assumptions!F55/1000 -> 111.02408 | E15: =D15*25 -> 2775.602

Sheet Unit Sales
A1: CAPCOM — Game Unit Sales & Franchise Analysis
A2: Units in millions unless noted
B4: FY2021 | C4: FY2022 | D4: FY2023 | E4: FY2024 | F4: FY2025 | G4: FY2026E | H4: FY2027E | I4: FY2028E | J4: Notes
A6: TOTAL UNIT SALES
A7: New Titles | B7: 12 | C7: 6 | D7: 16.6 | E7: 12 | F7: 16.5 | G7: 15 | H7: 18 | I7: 20
A8: Catalog Titles | B8: 20.1 | C8: 20.1 | D8: 25.1 | E8: 35.6 | F8: 35.4 | G8: 43 | H8: 45 | I8: 48
A9: Total Units | B9: =B7+B8 -> 32.1 | C9: =C7+C8 -> 26.1 | D9: =D7+D8 -> 41.7 | E9: =E7+E8 -> 47.6 | F9: =F7+F8 -> 51.9 | G9: =G7+G8 -> 58 | H9: =H7+H8 -> 63 | I9: =I7+I8 -> 68
A10: Catalog as % of Total | B10: =B8/B9 -> 0.62616822 | C10: =C8/C9 -> 0.77011494 | D10: =D8/D9 -> 0.60191847 | E10: =E8/E9 -> 0.74789916 | F10: =F8/F9 -> 0.68208092 | G10: =G8/G9 -> 0.74137931 | H10: =H8/H9 -> 0.71428571 | I10: =I8/I9 -> 0.70588235
A12: FY2026 TRACKING (9M ended Dec 2025)
A13: 9M Total Units (actual) | B13: 40.51 | J13: Record 9M total & catalog
A14: 9M Catalog Units (actual) | B14: 33.39
A15: 9M New Title Units (actual) | B15: =B13-B14 -> 7.12
A17: KEY FRANCHISE CUMULATIVE SALES (M units)
A18: Monster Hunter series | B18: >100M | J18: MH Wilds: 11M+ at Q3 FY26
A19: Resident Evil series | B19: >160M | J19: RE Requiem: Feb 27, 2026 launch
A20: Street Fighter series | B20: >54M | J20: SF6: >6M units, Switch 2 upside
A21: Devil May Cry series | B21: >32M | J21: DMC5: >10M (Netflix anime boost)
A22: Mega Man series | B22: >40M | J22: MMBN Legacy Collection performing well
A23: Dragon's Dogma series | B23: >11M | J23: DD2 catalog potential
A24: Ace Attorney series | B24: >12M | J24: New collection released FY26

Sheet Business & Industry
A1: CAPCOM (TSE: 9697) — BUSINESS & INDUSTRY ANALYSIS
A3: COMPETITIVE MOAT ANALYSIS
A4: Moat Factor | B4: Strength (1-5) | C4: Evidence | D4: Peer Avg | E4: Moat Width | F4: Durability
A5: IP Portfolio Depth | B5: 5 | C5: 8 franchises with 10M+ cumulative sales; RE 160M+, MH 100M+, SF 54M+ | D5: 3 | E5: Wide | F5: 10+ years
A6: Proprietary RE Engine | B6: 5 | C6: In-house engine; 10+ yrs dev; multi-platform; cost advantage vs Unreal/Unity licensing | D6: 2 | E6: Wide | F6: 10+ years
A7: Brand Recognition | B7: 5 | C7: 40+ yr heritage; cultural icons (Ryu, Leon, Rathalos); global awareness | D7: 3 | E7: Wide | F7: 10+ years
A8: Digital Distribution (93% digital) | B8: 4 | C8: 230+ countries; zero marginal cost; infinite shelf life; catalog flywheel | D8: 3 | E8: Wide | F8: 5-10 years
A9: Development Talent Retention | B9: 4 | C9: Osaka hub consolidation; 52.2% avg salary increase since 2021; 3,766 employees | D9: 3 | E9: Moderate | F9: 5-10 years
A10: Cross-Media Monetization | B10: 4 | C10: Netflix DMC anime → DMC5 sales revival; RE films/TV; MH movie; merchandise | D10: 2 | E10: Moderate | F10: 5-10 years
A11: Switching Costs (Franchise Loyalty) | B11: 4 | C11: MH community 100M+ strong; SF esports ecosystem; RE fandom spans 28 years | D11: 2 | E11: Moderate | F11: 10+ years
A12: Economies of Scale | B12: 4 | C12: RE Engine shared across all titles; R&D amortized over 50M+ annual units | D12: 3 | E12: Moderate | F12: 5-10 years
A13: Overall Moat Score | B13: =AVERAGE(B5:B12) -> 4.375 | C13: Out of 5.0 — Wide Moat
A15: MANAGEMENT QUALITY ASSESSMENT
A16: Metric | B16: FY2022 | C16: FY2023 | D16: FY2024 | E16: FY2025 | F16: Trend
A17: Return on Equity (ROE) | B17: 0.18 | C17: 0.212 | D17: 0.243 | E17: 0.248 | F17: ↑ Improving
A18: Return on Assets (ROA) | B18: 0.142 | C18: 0.157 | D18: 0.189 | E18: 0.174 | F18: ↑ Stable-High
A19: Operating Margin | B19: 0.34 | C19: 0.368 | D19: 0.375 | E19: 0.388 | F19: ↑ Expanding
A20: Revenue per Employee (¥M) | B20: 30 | C20: 33.5 | D20: 41.5 | E20: 45 | F20: ↑ Strong
A21: Consecutive Record Profits | B21: 9 | C21: 10 | D21: 11 | E21: 12 | F21: ↑ 12 years
A22: Dividend Payout Ratio | B22: 0.3 | C22: 0.3 | D22: 0.3 | E22: 0.3 | F22: → Consistent 30%
A23: Share Buyback (¥B) | B23: 0 | C23: 0 | D23: 0 | E23: 8.5 | F23: New in FY25
A24: Insider Ownership | B24: 0.227 | C24: 0.227 | D24: 0.227 | E24: 0.227 | F24: → Aligned 22.7%
A25: Management Score | B25: 9/10 | C25: Founder-led, skin-in-game (22.7%), 12yr record streak, disciplined capital allocation
A27: GAMING INDUSTRY & SECTOR GROWTH
A28: Metric | B28: 2024A | C28: 2025E | D28: 2026E | E28: 2027E | F28: Source
A29: Global Gaming Revenue ($B) | B29: 188 | C29: 200 | D29: 206 | E29: 215 | F29: Newzoo 2025
A30: Global Gaming CAGR | E30: 0.03 | F30: Newzoo (2025-28)
A31: Console Segment CAGR | E31: 0.047 | F31: Newzoo (2025-28)
A32: PC Segment CAGR | E32: 0.033 | F32: Newzoo (2025-28)
A33: Console+PC TAM ($B) | B33: 90 | C33: 95 | D33: 100 | E33: 108 | F33: Capcom IR 2025
A34: Capcom Market Share (Console+PC) | C34: 0.018 | D34: 0.019 | E34: 0.02 | F34: Derived
A35: Japan Gaming Sector Index YoY | C35: -0.08 | F35: TSE
A36: Digital Sales % of Industry | B36: 0.85 | C36: 0.87 | D36: 0.89 | E36: 0.91 | F36: Industry est.
A37: Capcom Digital Sales % | B37: 0.9 | C37: 0.932 | D37: 0.94 | E37: 0.95 | F37: Capcom IR
A38: Key Insight | B38: Capcom grows at 2-3x industry rate. Console+PC (Capcom's sweet spot) is fastest growing segment at 4.7% CAGR, well above mobile. Digital shift near-complete for Capcom (93%) = structurally higher margins than peers.
A40: ECONOMIES OF SCALE & OPERATING LEVERAGE
A41: Metric | B41: FY2021 | C41: FY2023 | D41: FY2025 | E41: FY2026E | F41: Interpretation
A42: Revenue (¥B) | B42: 95.3 | C42: 110.1 | D42: 169.6 | E42: 190 | F42: +99% rev growth
A43: R&D Investment (¥B) | B43: 28 | C43: 35 | D43: 52 | E43: 58.3 | F43: +108% R&D
A44: Operating Income (¥B) | B44: 42.9 | C44: 47.1 | D44: 65.8 | E44: 73 | F44: +70% OP — less than rev growth
...

Sheet Investment Thesis
A1: CAPCOM (TSE: 9697) — INVESTMENT THESIS & VARIANT VIEW
A3: VARIANT VIEW: WHY THE MARKET IS WRONG
A4: Market Concern | B4: Consensus View | C4: Our View | D4: Evidence | E4: Impact
A5: MH Wilds Launch Issues | B5: MH Wilds underperformed expectations; franchise may be peaking | C5: Temporary bug/performance issues, not demand failure — 11M units in <1 month proves TAM expansion | D5: Fastest-selling Capcom game ever; ¥6.4B deferred revenue for DLC/updates; MH World recovered similarly post-launch | E5: HIGH — stock overreacted 27% from peak
A6: Post-Peak Earnings Fear | B6: FY2025 was the cycle top; growth will slow meaningfully | C6: FY2026 guided at 13th consecutive record; RE Requiem + catalog + pachislo provide multi-year visibility | D6: Company guidance: ¥190B rev / ¥73B OP; 9M results tracking ahead with ¥115.3B rev (61% of FY); COO says "progressing very smoothly" | E6: HIGH — consensus EPS ¥130 has upside risk
A7: Japan Gaming Sector Weakness | B7: Japanese gaming stocks derated broadly; sector rotation out | C7: Capcom is being sold on sector beta, not fundamentals — creating opportunity | D7: Japan gaming index -8% while Capcom earnings +15%; Capcom margins 2x peer average; decoupling from weaker peers like Square Enix | E7: MEDIUM — sentiment will catch up to fundamentals
A8: Valuation Premium Justified? | B8: Capcom trades at 33x P/E vs peer avg 25x — too expensive | C8: Premium warranted: 2x industry margin, 12yr record streak, zero debt, 93% digital | D8: Capcom ROE 25% vs peer avg 12%; 3yr EPS CAGR 28% vs peer 8%; catalog model = more recurring than peers | E8: MEDIUM — multiple compression overdone
A9: Catalog Growth Sustainability | B9: Catalog sales will plateau as library ages | C9: Catalog accelerating, not decelerating — cross-media (Netflix, films) and new platforms drive rediscovery | D9: Catalog units: 20M→25M→36M→43M(E) over 4 years; DMC5 hit 10M+ after Netflix anime; Switch 2 ports = fresh catalog wave | E9: HIGH — market undervalues recurring revenue
A11: STOCK PRICE DRIVER ANALYSIS — WHAT MOVES CAPCOM?
A12: Driver Category | B12: Importance (1-5) | C12: Current Signal | D12: Direction | E12: Key Metric to Watch
A13: EPS Revisions | B13: 5 | C13: Positive — Q2 beat by 11%; 9M tracking ahead of full-year | D13: Bullish ↑ | E13: FY2026 OP consensus vs ¥73B guidance
A14: Title Launch Success | B14: 5 | C14: RE Requiem Feb 27 — 2M+ Steam wishlists; MH Wilds DLC pipeline | D14: Bullish ↑ | E14: RE9 first-week sales; MH Wilds DLC attach rate
A15: Revenue / Unit Sales Growth | B15: 4 | C15: 9M: 40.5M units (record); on track for 55M+ FY2026 | D15: Bullish ↑ | E15: Quarterly unit sales disclosure
A16: Narrative Change | B16: 4 | C16: Currently: "Japan gaming sector sell-off"; Needs to shift to: "best-in-class compounder" | D16: Neutral → | E16: Sector rotation signals; analyst upgrade cycle
A17: Market Sentiment / Risk-On | B17: 3 | C17: Global risk appetite moderate; Japan gaming derated | D17: Neutral → | E17: Nikkei 225; Japan small-cap growth flows
A18: Incremental Info (News Flow) | B18: 3 | C18: RE Requiem reviews Feb 27; Nintendo Direct (Switch 2); MH Wilds patch cycle | D18: Bullish ↑ | E18: Metacritic scores; Steam concurrent players
A19: Policy / Macro | B19: 2 | C19: JPY weakness benefits overseas earnings; BoJ rate path uncertain | D19: Neutral → | E19: USD/JPY; BoJ policy decisions
A20: Consumer Confidence | B20: 2 | C20: Gaming spending resilient; digital shift reduces price sensitivity | D20: Neutral → | E20: Global consumer confidence indices
A21: PRIMARY DRIVER | B21: EPS revisions + Title launch success drive 70%+ of price action. Focus: RE Requiem sales data (Feb 27+), FY2026 guidance upgrade potential (May 2026), MH Wilds DLC revenue realization.
A23: ORGANIC GROWTH DECOMPOSITION — SHORT-TERM vs LONG-TERM
A24: Growth Driver | B24: Timeframe | C24: Revenue Impact (¥B) | D24: Probability | E24: Status
A25: SHORT-TERM CATALYSTS (0-12 months)
A26: RE Requiem launch (Feb 27, 2026) | B26: 0-3 months | C26: 15-25 | D26: 90% | E26: 2M+ Steam wishlists; RE franchise never misses
A27: MH Wilds DLC / Title Updates | B27: 3-12 months | C27: 5-15 | D27: 85% | E27: ¥6.4B deferred revenue on balance sheet; update roadmap announced
A28: Street Fighter 6 Switch 2 launch | B28: 3-6 months | C28: 3-5 | D28: 80% | E28: Switch 2 announced June 2025; SF6 confirmed for platform
A29: Catalog sales momentum | B29: Ongoing | C29: 8-12 | D29: 95% | E29: 9M record 33.4M catalog units; DMC5, DD2, RE Village all accelerating
A30: Pachislo/Amusement Equipment surge | B30: 0-12 months | C30: 5-10 | D30: 80% | E30: 9M equipment revenue +74% YoY; operating profit +353%
A32: LONG-TERM STRUCTURAL DRIVERS (1-5 years)
A33: 100M annual unit sales target (COO KPI) | B33: 3-5 years | C33: 30-50 | D33: 60% | E33: Currently 52M→58M trajectory; requires IP expansion + new markets
A34: New dev facility (Osaka, completion 2027) | B34: 2-3 years | C34: 10-20 | D34: 75% | E34: ¥9.0B investment; enables larger parallel dev teams
A35: Non-core IP revival (MegaMan, Ace Attorney, DMC) | B35: 1-3 years | C35: 5-15 | D35: 70% | E35: COO explicitly named these IPs in 2025 Integrated Report
A36: Cross-media flywheel expansion | B36: 1-5 years | C36: 3-8 | D36: 65% | E36: Netflix DMC success; RE films/TV; potential MH animated series
A37: Emerging market penetration | B37: 2-5 years | C37: 5-15 | D37: 55% | E37: Digital distribution enables 230+ countries; APAC/LATAM growth
A38: 10%+ annual OP growth KPI (management target) | B38: Perpetual | D38: 80% | E38: 12 consecutive years achieved; culture of continuous improvement
A40: HOW CONSENSUS CONVERGES TO OUR VIEW
A41: Catalyst | B41: Expected Date | C41: Current Consensus | D41: Our Estimate | E41: Gap / Upside
A42: FY2026 EPS (¥) | B42: May 2026 | C42: ¥130 | D42: ¥145+ | E42: +12% upside to consensus
A43: RE Requiem first-month sales | B43: Mar 2026 | C43: 3-4M units | D43: 5-6M units | E43: RE franchise avg debut 4M+; wishlists suggest higher
A44: MH Wilds cumulative (FY2026 end) | B44: Mar 2026 | C44: 15M units | D44: 18-20M | E44: DLC + patches will reaccelerate; MH World hit 21M
A45: FY2027 Operating Profit | B45: May 2027 | C45: ¥80B | D45: ¥88-95B | E45: Catalog flywheel + RE9 + new IP underestimated
...

Sheet Market Setup
A1: CAPCOM (TSE: 9697) — MARKET SETUP & SENTIMENT ANALYSIS
A3: SHAREHOLDER COMPOSITION (as of Mar 31, 2025)
A4: Shareholder Category | B4: Shares (000s) | C4: % of Outstanding | D4: Type | E4: Implications
A5: Tsujimoto Family (Crossroad + direct) | B5: 121000 | C5: 0.227 | D5: Insider / Founder | E5: Aligned with long-term value; unlikely sellers
A6: Master Trust Bank of Japan | B6: 76300 | C6: 0.143 | D6: Domestic Institutional | E6: Passive; tracks indices; provides floor
A7: Custody Bank of Japan | B7: 45000 | C7: 0.084 | D7: Domestic Institutional | E7: Passive custody; stable holder
A8: Foreign Institutional | B8: 160000 | C8: 0.3 | D8: Active + Passive | E8: Growth-oriented; potential incremental buyers on catalysts
A9: Domestic Retail | B9: 55000 | C9: 0.103 | D9: Retail | E9: Sentiment-driven; can amplify moves
A10: Treasury Stock | B10: 106789 | C10: 0.2 | D10: Company-held | E10: Buyback buffer; supports EPS
A11: Other / Float | B11: 75000 | C11: 0.141 | D11: Various | E11: Available for trading
A12: Total Shares Outstanding | B12: 533011 | C12: thousands
A14: SETUP: PRICING vs NON-PRICING (What's Priced In?)
A15: Factor | B15: Priced In? | C15: Market Implies | D15: Our View | E15: Upside if Re-priced
A16: FY2026 guidance (¥73B OP) | B16: YES — Fully priced | C16: Current P/E ~25x on ¥145 TTM EPS | D16: Guidance is conservative; likely beat | E16: Minimal
A17: MH Wilds disappointment narrative | B17: YES — Overpriced | C17: Market treats as structural decline | D17: 11M units = massive success; bugs fixable | E17: HIGH — narrative reversal = 10-15% move
A18: RE Requiem success | B18: PARTIALLY | C18: Some upside expected but not blockbuster | D18: 2M+ wishlists → likely 5M+ units | E18: MODERATE — 5-8% move on strong debut
A19: Japan sector derating | B19: YES — Overpriced | C19: Capcom tarred with Square Enix/Konami brush | D19: Capcom margins 2x peers; shouldn't trade in line | E19: HIGH — sector re-rating = 10%+ move
A20: Catalog flywheel acceleration | B20: NO — Underpriced | C20: Market models flat catalog growth | D20: Catalog growing 20%+ YoY; structural shift | E20: HIGH — recurring revenue re-rating
A21: MH Wilds DLC revenue (¥6.4B deferred) | B21: NO — Not priced | C21: Market ignores deferred revenue | D21: DLC will add ¥5-10B incremental over 18 months | E21: HIGH — pure upside surprise
A22: Switch 2 catalog port cycle | B22: NO — Not priced | C22: Not in estimates | D22: Similar to Switch 1 catalog boost in 2017-19 | E22: MODERATE — gradual upside
A23: FY2027 guidance upgrade | B23: NO — Not priced | C23: No visibility yet | D23: If FY2026 beats → FY2027 will guide higher | E23: HIGH — forward multiple expansion
A25: INCREMENTAL BUYER ANALYSIS
A26: Buyer Type | B26: Trigger | C26: Est. Buying Power | D26: Timeline | E26: Likelihood
A27: Sell-side upgrades (12 Buy, 0 Sell) | B27: RE Requiem strong sales / FY beat | C27: Influences $50B+ AUM | D27: Q1-Q2 2026 | E27: HIGH
A28: Japan gaming sector rotation | B28: Sector earnings recovery / Nintendo Switch 2 cycle | C28: Sector-wide flows | D28: H1 2026 | E28: MODERATE
A29: Foreign institutional inflows | B29: Weak JPY + strong earnings → Japan equity appeal | C29: $5-10B incremental to sector | D29: Ongoing | E29: MODERATE
A30: Passive index rebalancing | B30: Capcom re-weights in TOPIX/MSCI Japan on mkt cap recovery | C30: Automatic flows | D30: On price recovery | E30: HIGH
A31: Retail / momentum traders | B31: Stock breaking above 200-DMA (currently ¥3,850-4,000) | C31: Amplifies moves | D31: On breakout | E31: MODERATE
A32: Value buyers on P/E compression | B32: P/E at 25x near 3-year low on TTM | C32: Quality-value crossover | D32: Now | E32: Active already
A34: BEAR THESIS vs BULL THESIS
A35: BEAR CASE | C35: BULL CASE
A36: MH Wilds is genuinely peaking; franchise fatigue sets in | C36: MH Wilds is fastest-selling Capcom game ever; franchise expanding to new audiences globally
A37: Japan gaming sector continues to de-rate on macro concerns | C37: Capcom decouples from weak peers on superior fundamentals; quality premium returns
A38: RE Requiem disappoints critically (unlikely given track record) | C38: RE Requiem joins RE2R, RE4R as critically acclaimed; drives 5M+ unit sales and catalog halo
A39: Competition from GTA VI absorbs consumer spending in 2026 | C39: GTA VI is cross-platform — grows overall market; Capcom benefits from enlarged gaming TAM
A40: Management gets complacent after 12-year streak | C40: Founder-family ownership (22.7%) ensures long-term alignment; 100M unit target = ambition intact
A41: Valuation multiple compresses further from 33x → 20x | C41: Multiple expands from 25x → 30-35x as market recognizes recurring catalog revenue quality
A42: Probability Weighting | B42: Bear case: 20% probability | Base case: 55% probability | Bull case: 25% probability → Weighted toward base-to-bull outcome

Sheet Risk-Reward
A1: CAPCOM (TSE: 9697) — RISK-REWARD & INVESTMENT RECOMMENDATION
A3: PROBABILITY-WEIGHTED RISK-REWARD ANALYSIS
A4: Scenario | B4: Probability | C4: Target Price (¥) | D4: Return from ¥3,670 | E4: Weighted Return
A5: Bear Case | B5: 0.2 | C5: 2800 | D5: =(C5-3670)/3670 -> -0.23705722 | E5: =B5*D5 -> -0.047411444
A6: Base Case | B6: 0.55 | C6: 4800 | D6: =(C6-3670)/3670 -> 0.30790191 | E6: =B6*D6 -> 0.16934605
A7: Bull Case | B7: 0.25 | C7: 5400 | D7: =(C7-3670)/3670 -> 0.47138965 | E7: =B7*D7 -> 0.11784741
A8: Expected (Probability-Weighted) Return | E8: =SUM(E5:E7) -> 0.23978202
A9: Expected Target Price (¥) | E9: =SUMPRODUCT(B5:B7,C5:C7) -> 4550
A10: Risk-Reward Ratio (Upside:Downside) | E10: =IFERROR(ABS((C6-3670)/(3670-C5)),"N/A") -> 1.2988506
A12: SCENARIO ASSUMPTIONS DETAIL
A13: Assumption | B13: Bear Case | C13: Base Case | D13: Bull Case | E13: Rationale
A14: FY2026 Revenue (¥B) | B14: 175 | C14: 195 | D14: 210 | E14: Bear: miss guidance; Base: meet+; Bull: upside from RE9
A15: FY2026 Operating Margin | B15: 36.0% | C15: 39.0% | D15: 41.0% | E15: Bear: dev cost overruns; Base: guidance; Bull: catalog mix shift
A16: FY2026 EPS (¥) | B16: ~95 | C16: ~105 | D16: ~115 | E16: Flows from revenue × margin assumptions
A17: Exit P/E Multiple | B17: 22x | C17: 30x | D17: 35x | E17: Bear: sector derates; Base: premium maintains; Bull: re-rates
A18: RE Requiem Sales (M units) | B18: 2.5 | C18: 5.0 | D18: 7.0 | E18: Bear: critical miss; Base: franchise avg; Bull: RE2R-level hit
A19: MH Wilds Cumulative (M) | B19: 13 | C19: 18 | D19: 22 | E19: Bear: no recovery; Base: DLC-driven; Bull: MH World trajectory
A20: Catalog Growth YoY | B20: 5% | C20: 20% | D20: 30% | E20: Bear: plateau; Base: trend continues; Bull: Switch 2 + media boost
A21: Target Price (¥) | B21: 2800 | C21: 4800 | D21: 5400 | E21: Bear: ¥95 × 22x + cash; Base: ¥105 × 30x; Bull: ¥115 × 35x
A22: Return from ¥3,670 | B22: -24% | C22: +31% | D22: +47%
A24: KEY RISKS — STRUCTURED ANALYSIS
A25: Risk | B25: Severity (1-5) | C25: Probability | D25: Impact on Thesis | E25: Mitigant
A26: RE Requiem critical/commercial disappointment | B26: 4 | C26: 15% | D26: Would delay narrative reversal; -5-10% on price | E26: RE franchise has 95%+ Metacritic hit rate; 2M+ wishlists de-risk
A27: MH Wilds fails to recover (permanent franchise damage) | B27: 5 | C27: 10% | D27: Would undermine long-term thesis; -15-20% | E27: 11M sold = massive install base; MH World had similar post-launch issues and recovered to 21M
A28: Japan gaming sector further derates on macro | B28: 3 | C28: 25% | D28: Delay in multiple expansion; -5-10% | E28: Capcom trades on its own fundamentals over time; foreign investor interest provides floor
A29: GTA VI launches and absorbs consumer wallet share | B29: 3 | C29: 30% | D29: Temporary sales pressure in H2 2026 | E29: Capcom titles target different demographics; overall TAM grows with GTA VI
A30: JPY strengthens materially (>10%) | B30: 2 | C30: 20% | D30: Reduces overseas revenue in yen terms | E30: 60%+ revenue is domestic digital; natural hedge from global pricing
A31: Key talent departure / management transition | B31: 3 | C31: 10% | D31: Would shake confidence in execution | E31: Deep bench: Ryozo Tsujimoto, Jun Takeuchi, Yoichi Egawa all experienced leaders
A32: Rising development costs squeeze margins | B32: 3 | C32: 20% | D32: Margin compression risk for FY2027+ | E32: RE Engine in-house advantage; new Osaka facility for efficiency; catalog offsets
A33: Regulatory risk (loot boxes, age ratings) | B33: 2 | C33: 15% | D33: Could limit monetization in some markets | E33: Capcom uses premium pricing, not aggressive MTX; minimal exposure
A34: Cybersecurity breach (repeat of 2020 ransomware) | B34: 3 | C34: 10% | D34: Reputational damage; dev delays | E34: Capcom invested heavily in security post-2020; ISO27001 certified
A36: INVESTMENT RECOMMENDATION
A37: Recommendation | B37: BUY
A38: Current Price | B38: ¥3,670
A39: 12-Month Target Price | B39: ¥4,800 (Base Case)
A40: Upside Potential | B40: +30.8%
A41: Risk-Reward Ratio | B41: See E10 (formula-driven)
A42: Expected Return (Prob-Weighted) | B42: See E8 (formula-driven)
A43: Investment Horizon | B43: 12-18 months
A44: Conviction Level | B44: HIGH (8/10)
...

Sheet Competitor Analysis
A1: CAPCOM vs PEERS — COMPREHENSIVE COMPETITOR COMPARISON
A3: FINANCIAL METRICS COMPARISON (LTM / FY2025)
A4: Metric | B4: Capcom | C4: Nintendo | D4: Square Enix | E4: Konami | F4: Bandai Namco | G4: EA | H4: Peer Avg
A5: Revenue (Local Ccy, B) | B5: ¥169.6B | C5: ¥1,671B | D5: ¥356B | E5: ¥370B | F5: ¥1,060B | G5: $7.6B
A6: Revenue Growth YoY | B6: 0.113 | C6: 0.35 | D6: 0.05 | E6: 0.1 | F6: 0.08 | G6: 0.02 | H6: =AVERAGE(C6:G6) -> 0.12
A7: Gross Margin | B7: 0.582 | C7: 0.57 | D7: 0.48 | E7: 0.5 | F7: 0.42 | G7: 0.73 | H7: =AVERAGE(C7:G7) -> 0.54
A8: Operating Margin | B8: 0.388 | C8: 0.33 | D8: 0.12 | E8: 0.22 | F8: 0.1 | G8: 0.2 | H8: =AVERAGE(C8:G8) -> 0.194
A9: Net Margin | B9: 0.286 | C9: 0.28 | D9: 0.08 | E9: 0.15 | F9: 0.06 | G9: 0.14 | H9: =AVERAGE(C9:G9) -> 0.142
A10: ROE | B10: 0.248 | C10: 0.18 | D10: 0.06 | E10: 0.2 | F10: 0.08 | G10: 0.35 | H10: =AVERAGE(C10:G10) -> 0.174
A11: EV/EBITDA | B11: 18.8 | C11: 14 | D11: 8.5 | E11: 15 | F11: 12 | G11: 16 | H11: =AVERAGE(C11:G11) -> 13.1
A12: P/E Ratio | B12: 25.1 | C12: 20 | D12: 25 | E12: 28 | F12: 22 | G12: 30 | H12: =AVERAGE(C12:G12) -> 25
A13: EV/Revenue | B13: 8.7 | C13: 6 | D13: 1.5 | E13: 4 | F13: 1.5 | G13: 5.5 | H13: =AVERAGE(C13:G13) -> 3.7
A14: Dividend Yield | B14: 0.011 | C14: 0.025 | D14: 0.015 | E14: 0.01 | F14: 0.02 | G14: 0.005 | H14: =AVERAGE(C14:G14) -> 0.015
A15: Net Cash/(Debt) Position | B15: Net Cash ¥97B | C15: Net Cash ¥1.1T | D15: Net Cash ¥50B | E15: Net Cash ¥20B | F15: Net Cash ¥120B | G15: Net Debt $2B
A16: 3-Yr Revenue CAGR | B16: 0.155 | C16: 0.08 | D16: 0.05 | E16: 0.1 | F16: 0.06 | G16: 0.02 | H16: =AVERAGE(C16:G16) -> 0.062
A17: 3-Yr EPS CAGR | B17: 0.28 | C17: 0.1 | D17: 0.03 | E17: 0.15 | F17: 0.04 | G17: 0.08 | H17: =AVERAGE(C17:G17) -> 0.08
A18: Beta | B18: 0.58 | C18: 0.65 | D18: 0.9 | E18: 0.75 | F18: 0.8 | G18: 0.85 | H18: =AVERAGE(C18:G18) -> 0.79
A19: Digital Sales % | B19: 0.932 | C19: 0.35 | D19: 0.65 | E19: 0.7 | F19: 0.5 | G19: 0.9 | H19: =AVERAGE(C19:G19) -> 0.62
A20: Catalog % of Unit Sales | B20: 0.683 | C20: 0.4 | D20: 0.3 | E20: 0.35 | F20: 0.3 | G20: 0.6 | H20: =AVERAGE(C20:G20) -> 0.39
A22: CAPCOM COMPETITIVE ADVANTAGES — WHERE CAPCOM LEADS
A23: #1 Operating Margin | B23: 38.8% — nearly 2x the peer average of ~19%. Only EA approaches, and EA has declining revenue growth.
A24: #1 EPS Growth | B24: 28% 3-year CAGR vs peer average 8%. Fastest earnings compounder in the sector.
A25: #1 Digital Transition | B25: 93.2% digital — highest in console/PC gaming. Nintendo at 35%. This = structurally higher margins.
A26: #1 Catalog Monetization | B26: 68.3% of sales from catalog (peer avg ~35%). Near-zero marginal cost recurring revenue.
A27: #1 Lowest Beta | B27: 0.58 — most defensive name in gaming. Lower risk profile than all major peers.
A28: #1 IP Concentration (Quality) | B28: 8 franchises >10M cumulative sales. Deep quality > breadth. Better hit rate than peers.
A29: Justified Premium | B29: Trades at 25x P/E (below recent avg of 33x). Premium warranted by 2x margins, 3x growth, best catalog model.
